<?xml version="1.0" encoding="utf-8" ?>
<!-- =================================================================================== -->
<!-- |    This document was autogenerated by xacro from /home/tong/catkin_ps/src/new.xacro | -->
<!-- |    EDITING THIS FILE BY HAND IS NOT RECOMMENDED                                 | -->
<!-- =================================================================================== -->
<!-- =================================================================================== -->
<!-- |    This document was autogenerated by xacro from ur5_robot.urdf.xacro           | -->
<!-- |    EDITING THIS FILE BY HAND IS NOT RECOMMENDED                                 | -->
<!-- =================================================================================== -->
<robot name="arm">
    <gazebo>
        <plugin filename="libgazebo_ros_control.so" name="ros_control">
            <!--robotNamespace>/</robotNamespace-->
            <!--robotSimType>gazebo_ros_control/DefaultRobotHWSim</robotSimType-->
        </plugin>
    </gazebo>
    <!-- BASE LINK F1 -->
    <link name="base_link">
        
<inertial>
            <origin rpy="0 0 0" xyz="0 0 0" />
            <mass value="10" />
            <inertia ixx="0.0003533" ixy="0.0" ixz="0.0" iyy="0.000586875" iyz="0.0" izz="0.0004" />
        </inertial>

        <collision>
            <origin rpy="0 0 0" xyz="0 0 0" />
            <geometry>
                <mesh filename="package://robot_description/meshes/arm/h1.dae" />
            </geometry>
        </collision>
        <visual>
            <origin rpy="0.0 0 0" xyz="0 0 0" />
            <geometry>
                <mesh filename="package://robot_description/meshes/arm/h1.dae" />
            </geometry>
            <material name="LightGrey">
                <color rgba="0.7 0.7 0.7 1.0" />
            </material>
        </visual>
    </link>
    <joint name="arm_joint_F2" type="revolute">
        <parent link="base_link" />
        <child link="arm_link_F2" />
        <origin rpy="0 0 0" xyz="0 0 0.235" />
        <limit effort="1000.0" lower="-3.14" upper="3.14" velocity="3.14" />
        <axis xyz="0 0 1" />
        <dynamics damping="0.0" friction="0.0" />
    </joint>
    <!-- ARM LINK F2 -->
    <link name="arm_link_F2">
        
<inertial>
            <origin rpy="0 0 0" xyz="0 0 0" />
            <mass value="10" />
            <inertia ixx="0.0003533" ixy="0.0" ixz="0.0" iyy="0.000586875" iyz="0.0" izz="0.0004" />
        </inertial>

        <collision>
            <origin rpy="0 0 0" xyz="0 0 0" />
            <geometry>
                <mesh filename="package://robot_description/meshes/arm/h2.dae" />
            </geometry>
        </collision>
        <visual>
            <origin rpy="0.0 0 0" xyz="0 0 0" />
            <geometry>
                <mesh filename="package://robot_description/meshes/arm/h2.dae" />
            </geometry>
            <material name="LightGrey">
                <color rgba="0.7 0.7 0.7 1.0" />
            </material>
        </visual>
    </link>
    <joint name="arm_joint_F3" type="revolute">
        <parent link="arm_link_F2" />
        <child link="arm_link_F3" />
        <origin rpy="0 0 0" xyz="0.055 0.165 0.195" />
        <limit effort="1000.0" lower="-3.14" upper="3.14" velocity="3.14" />
        <axis xyz="1 0 0" />
        <dynamics damping="0.0" friction="0.0" />
    </joint>
    <!-- ARM LINK F3 -->
    <link name="arm_link_F3">
        
<inertial>
            <origin rpy="0 0 0" xyz="0 0 0" />
            <mass value="1" />
            <inertia ixx="0.0003533" ixy="0.0" ixz="0.0" iyy="0.000586875" iyz="0.0" izz="0.0004" />
        </inertial>

        <collision>
            <origin rpy="0 0 0" xyz="0 0 0" />
            <geometry>
                <mesh filename="package://robot_description/meshes/arm/h3.dae" />
            </geometry>
        </collision>
        <visual>
            <origin rpy="0.0 0 0" xyz="0 0 0" />
            <geometry>
                <mesh filename="package://robot_description/meshes/arm/h3.dae" />
            </geometry>
            <material name="LightGrey">
                <color rgba="0.7 0.7 0.7 1.0" />
            </material>
        </visual>
    </link>
    <joint name="arm_joint_F4" type="revolute">
        <parent link="arm_link_F3" />
        <child link="arm_link_F4" />
        <origin rpy="0 0 0" xyz="0.072 0 0.55" />
        <limit effort="1000.0" lower="-3.14" upper="3.14" velocity="3.14" />
        <axis xyz="1 0 0" />
        <dynamics damping="0.0" friction="0.0" />
    </joint>
    <!-- ARM LINK F4 -->
    <link name="arm_link_F4">
        
<inertial>
            <origin rpy="0 0 0" xyz="0 0 0" />
            <mass value="0.1" />
            <inertia ixx="0.0003533" ixy="0.0" ixz="0.0" iyy="0.000586875" iyz="0.0" izz="0.0004" />
        </inertial>

        <collision>
            <origin rpy="0 0 0" xyz="0 0 0" />
            <geometry>
                <mesh filename="package://robot_description/meshes/arm/h4.dae" />
            </geometry>
        </collision>
        <visual>
            <origin rpy="0.0 0 0" xyz="0 0 0" />
            <geometry>
                <mesh filename="package://robot_description/meshes/arm/h4.dae" />
            </geometry>
            <material name="LightGrey">
                <color rgba="0.7 0.7 0.7 1.0" />
            </material>
        </visual>
    </link>
    <joint name="arm_joint_F5" type="revolute">
        <parent link="arm_link_F4" />
        <child link="arm_link_F5" />
        <origin rpy="0 0 0" xyz="-0.121 -0.210 0.259" />
        <limit effort="1000.0" lower="-3.14" upper="3.14" velocity="3.14" />
        <axis xyz="0 0 1" />
        <dynamics damping="0.0" friction="0.0" />
    </joint>
    <!-- ARM LINK F5 -->
    <link name="arm_link_F5">
        
<inertial>
            <origin rpy="0 0 0" xyz="0 0 0" />
            <mass value="0.1" />
            <inertia ixx="0.0003533" ixy="0.0" ixz="0.0" iyy="0.000586875" iyz="0.0" izz="0.0004" />
        </inertial>

        <collision>
            <origin rpy="0 0 0" xyz="0 0 0" />
            <geometry>
                <mesh filename="package://robot_description/meshes/arm/h5.dae" />
            </geometry>
        </collision>
        <visual>
            <origin rpy="0.0 0 0" xyz="0 0 0" />
            <geometry>
                <mesh filename="package://robot_description/meshes/arm/h5.dae" />
            </geometry>
            <material name="LightGrey">
                <color rgba="0.7 0.7 0.7 1.0" />
            </material>
        </visual>
    </link>
    <joint name="arm_joint_F6" type="revolute">
        <parent link="arm_link_F5" />
        <child link="arm_link_F6" />
        <origin rpy="0 0 0" xyz="0.0865 0 0.4445" />
        <limit effort="1000.0" lower="-3.14" upper="3.14" velocity="3.14" />
        <axis xyz="1 0 0" />
        <dynamics damping="0.0" friction="0.0" />
    </joint>
    <!-- ARM LINK F6 -->
    <link name="arm_link_F6">
        
<inertial>
            <origin rpy="0 0 0" xyz="0 0 0" />
            <mass value="0.1" />
            <inertia ixx="0.0003533" ixy="0.0" ixz="0.0" iyy="0.000586875" iyz="0.0" izz="0.0004" />
        </inertial>

        <collision>
            <origin rpy="0 0 0" xyz="0 0 0" />
            <geometry>
                <mesh filename="package://robot_description/meshes/arm/h6.dae" />
            </geometry>
        </collision>
        <visual>
            <origin rpy="0.0 0 0" xyz="0 0 0" />
            <geometry>
                <mesh filename="package://robot_description/meshes/arm/h6.dae" />
            </geometry>
            <material name="LightGrey">
                <color rgba="0.7 0.7 0.7 1.0" />
            </material>
        </visual>
    </link>
    <joint name="arm_joint_F7" type="fixed">
        <parent link="arm_link_F6" />
        <child link="arm_link_F7" />
        <origin rpy="0 0 0" xyz="-0.0915 0 0.115" />
        <axis xyz="0 0 1" />
        <dynamics damping="0.0" friction="0.0" />
    </joint>
    <!-- ARM LINK F7 -->
    <link name="arm_link_F7">
        
<inertial>
            <origin rpy="0 0 0" xyz="0 0 0" />
            <mass value="0.1" />
            <inertia ixx="0.0003533" ixy="0.0" ixz="0.0" iyy="0.000586875" iyz="0.0" izz="0.0004" />
        </inertial>

        <collision>
            <origin rpy="0 0 0" xyz="0 0 0" />
            <geometry>
                <mesh filename="package://robot_description/meshes/arm/h8.dae" />
            </geometry>
        </collision>
        <visual>
            <origin rpy="0.0 0 0" xyz="0 0 0" />
            <geometry>
                <mesh filename="package://robot_description/meshes/arm/h8.dae" />
            </geometry>
            <material name="LightGrey">
                <color rgba="0.7 0.7 0.7 1.0" />
            </material>
        </visual>
    </link>
    <joint name="arm_joint_F8" type="revolute">
        <parent link="arm_link_F7" />
        <child link="end" />
        <origin rpy="0 0 0" xyz="0.0 0 0.0045" />
        <limit effort="1000.0" lower="-3.14" upper="3.14" velocity="3.14" />
        <axis xyz="0 0 1" />
        <dynamics damping="0.0" friction="0.0" />
    </joint>
    <!-- end -->
    <link name="end">
        
<inertial>
            <origin rpy="0 0 0" xyz="0 0 0" />
            <mass value="0.01" />
            <inertia ixx="0.0003533" ixy="0.0" ixz="0.0" iyy="0.000586875" iyz="0.0" izz="0.0004" />
        </inertial>

        <collision>
            <origin rpy="0 0 0" xyz="0 0 0" />
            <geometry>
                <mesh filename="package://robot_description/meshes/arm/end.dae" />
            </geometry>
        </collision>
        <visual>
            <origin rpy="0.0 0 0" xyz="0 0 0" />
            <geometry>
                <mesh filename="package://robot_description/meshes/arm/end.dae" />
            </geometry>
        </visual>
    </link>
    
<transmission name="trans1">
        <type>transmission_interface/SimpleTransmission</type>
        <joint name="arm_joint_F2">
            <hardwareInterface>hardware_interface/PositionJointInterface</hardwareInterface>
        </joint>
        <actuator name="motor1">
            <mechanicalReduction>1</mechanicalReduction>
        </actuator>
    </transmission>
    <transmission name="trans2">
        <type>transmission_interface/SimpleTransmission</type>
        <joint name="arm_joint_F3">
            <hardwareInterface>hardware_interface/PositionJointInterface</hardwareInterface>
        </joint>
        <actuator name="motor2">
            <mechanicalReduction>1</mechanicalReduction>
        </actuator>
    </transmission>
    <transmission name="trans3">
        <type>transmission_interface/SimpleTransmission</type>
        <joint name="arm_joint_F4">
            <hardwareInterface>hardware_interface/PositionJointInterface</hardwareInterface>
        </joint>
        <actuator name="motor3">
            <mechanicalReduction>1</mechanicalReduction>
        </actuator>
    </transmission>
    <transmission name="trans4">
        <type>transmission_interface/SimpleTransmission</type>
        <joint name="arm_joint_F5">
            <hardwareInterface>hardware_interface/PositionJointInterface</hardwareInterface>
        </joint>
        <actuator name="motor4">
            <mechanicalReduction>1</mechanicalReduction>
        </actuator>
    </transmission>
    <transmission name="trans5">
        <type>transmission_interface/SimpleTransmission</type>
        <joint name="arm_joint_F6">
            <hardwareInterface>hardware_interface/PositionJointInterface</hardwareInterface>
        </joint>
        <actuator name="motor5">
            <mechanicalReduction>1</mechanicalReduction>
        </actuator>
    </transmission>
    <transmission name="trans6">
        <type>transmission_interface/SimpleTransmission</type>
        <joint name="arm_joint_F8">
            <hardwareInterface>hardware_interface/PositionJointInterface</hardwareInterface>
        </joint>
        <actuator name="motor6">
            <mechanicalReduction>1</mechanicalReduction>
        </actuator>
    </transmission>
    <gazebo reference="arm_link_F2">
        <selfCollide>true</selfCollide>
    </gazebo>
    <gazebo reference="arm_link_F3">
        <selfCollide>true</selfCollide>
    </gazebo>
    <gazebo reference="arm_link_F4">
        <selfCollide>true</selfCollide>
    </gazebo>
    <gazebo reference="arm_link_F5">
        <selfCollide>true</selfCollide>
    </gazebo>
    <gazebo reference="arm_link_F6">
        <selfCollide>true</selfCollide>
    </gazebo>
    <gazebo reference="arm_link_F8">
        <selfCollide>true</selfCollide>
    </gazebo>
    <link name="world" />
    <joint name="world_joint" type="fixed">
        <parent link="world" />
        <child link="base_link" />
        <origin rpy="0.0 0.0 0.0" xyz="0.0 0.0 0.0" />
    </joint>
    <transmission name="trans_arm_joint_F2">
        <type>transmission_interface/SimpleTransmission</type>
        <joint name="arm_joint_F2">
            <hardwareInterface>hardware_interface/EffortJointInterface</hardwareInterface>
        </joint>
        <actuator name="arm_joint_F2_motor">
            <hardwareInterface>hardware_interface/EffortJointInterface</hardwareInterface>
            <mechanicalReduction>1</mechanicalReduction>
        </actuator>
    </transmission>
    <transmission name="trans_arm_joint_F3">
        <type>transmission_interface/SimpleTransmission</type>
        <joint name="arm_joint_F3">
            <hardwareInterface>hardware_interface/EffortJointInterface</hardwareInterface>
        </joint>
        <actuator name="arm_joint_F3_motor">
            <hardwareInterface>hardware_interface/EffortJointInterface</hardwareInterface>
            <mechanicalReduction>1</mechanicalReduction>
        </actuator>
    </transmission>
    <transmission name="trans_arm_joint_F4">
        <type>transmission_interface/SimpleTransmission</type>
        <joint name="arm_joint_F4">
            <hardwareInterface>hardware_interface/EffortJointInterface</hardwareInterface>
        </joint>
        <actuator name="arm_joint_F4_motor">
            <hardwareInterface>hardware_interface/EffortJointInterface</hardwareInterface>
            <mechanicalReduction>1</mechanicalReduction>
        </actuator>
    </transmission>
    <transmission name="trans_arm_joint_F5">
        <type>transmission_interface/SimpleTransmission</type>
        <joint name="arm_joint_F5">
            <hardwareInterface>hardware_interface/EffortJointInterface</hardwareInterface>
        </joint>
        <actuator name="arm_joint_F5_motor">
            <hardwareInterface>hardware_interface/EffortJointInterface</hardwareInterface>
            <mechanicalReduction>1</mechanicalReduction>
        </actuator>
    </transmission>
    <transmission name="trans_arm_joint_F6">
        <type>transmission_interface/SimpleTransmission</type>
        <joint name="arm_joint_F6">
            <hardwareInterface>hardware_interface/EffortJointInterface</hardwareInterface>
        </joint>
        <actuator name="arm_joint_F6_motor">
            <hardwareInterface>hardware_interface/EffortJointInterface</hardwareInterface>
            <mechanicalReduction>1</mechanicalReduction>
        </actuator>
    </transmission>
    <transmission name="trans_arm_joint_F8">
        <type>transmission_interface/SimpleTransmission</type>
        <joint name="arm_joint_F8">
            <hardwareInterface>hardware_interface/EffortJointInterface</hardwareInterface>
        </joint>
        <actuator name="arm_joint_F8_motor">
            <hardwareInterface>hardware_interface/EffortJointInterface</hardwareInterface>
            <mechanicalReduction>1</mechanicalReduction>
        </actuator>
    </transmission>
    <gazebo>
        <plugin name="gazebo_ros_control" filename="libgazebo_ros_control.so">
            <robotNamespace>/</robotNamespace>
        </plugin>
    </gazebo>
</robot>
